<?xml version ="1.0"?>
<robot name ="my_robot" xmlns:xacro="http://www.ros.org/wiki/xacro">

<xacro:macro name="caster" params="prefix xyz">
<link name="${prefix}_yaw_link">
  <inertial>
    <origin xyz="0 0 0" rpy="0 1.57 1.57"/>
    <mass value="0.5"/> 
    <inertia ixx="0.0002" iyy="0.0002" izz="0.0003" ixy="0" ixz="0" iyz="0"/>
  </inertial>

  <visual>
    <origin xyz="0 0 0" rpy="0 1.57 1.57"/>
    <geometry>
      <cylinder length="0.019" radius="0.025"/>
    </geometry>
    <material name="blue"/>
  </visual>

  <collision>
    <origin xyz="0 0 0" rpy="0 1.57 1.57"/>
    <geometry>
      <cylinder length="0.019" radius="0.025"/>
    </geometry>
  </collision>
</link>

<joint name="${prefix}_yaw_joint" type="continuous">
  <parent link="chassis"/>
  <child link="${prefix}_yaw_link"/>
  <origin xyz="${xyz}" rpy="0 0 0"/>
  <axis xyz="0 0 1"/>
  <limit effort="1000.0" velocity="100.0"/>
  <dynamics damping="0.0" friction="0.1"/>
</joint>

<link name="${prefix}_pitch_link">
  <inertial>
    <origin xyz="0 0 0" rpy="0 1.57 1.57"/>
    <mass value="0.5"/> 
    <inertia ixx="0.0002" iyy="0.0002" izz="0.0003" ixy="0" ixz="0" iyz="0"/>
  </inertial>

  <visual>
    <origin xyz="0 0 0" rpy="0 1.57 1.57"/>
    <geometry>
      <cylinder length="0.019" radius="0.025"/>
    </geometry>
    <material name="blue"/>
  </visual>

  <collision>
    <origin xyz="0 0 0" rpy="0 1.57 1.57"/>
    <geometry>
      <cylinder length="0.019" radius="0.025"/>
    </geometry>
  </collision>
</link>

<joint name="${prefix}_pitch_joint" type="continuous">
  <parent link="${prefix}_roll_link"/>
  <child link="${prefix}_pitch_link"/>
  <origin xyz="0 0 0" rpy="0 0 0"/>
  <axis xyz="0 1 0"/>
  <limit effort="1000.0" velocity="100.0"/>
  <dynamics damping="0.0" friction="0.1"/>
</joint>

<link name="${prefix}_roll_link">
  <inertial>
    <origin xyz="0 0 0" rpy="0 1.57 1.57"/>
    <mass value="0.5"/> 
    <inertia ixx="0.0002" iyy="0.0002" izz="0.0003" ixy="0" ixz="0" iyz="0"/>
  </inertial>

  <visual>
    <origin xyz="0 0 0" rpy="0 1.57 1.57"/>
    <geometry>
      <cylinder length="0.019" radius="0.025"/>
    </geometry>
    <material name="blue"/>
  </visual>

  <collision>
    <origin xyz="0 0 0" rpy="0 1.57 1.57"/>
    <geometry>
      <cylinder length="0.019" radius="0.025"/>
    </geometry>
  </collision>
</link>

<joint name="${prefix}_roll_joint" type="continuous">
  <parent link="${prefix}_yaw_link"/>
  <child link="${prefix}_roll_link"/>
  <origin xyz="0 0 0" rpy="0 0 0"/>
  <axis xyz="1 0 0"/>
  <limit effort="1000.0" velocity="100.0"/>
  <dynamics damping="0.0" friction="0.1"/>
</joint>


<gazebo reference="${prefix}_yaw_link">
  <material>Gazebo/Blue</material>
  <kp>1000000000000000000000000000.0</kp>
    <kd>1000000000000000000000000000.0</kd>
    <mu1>0.1</mu1>
    <mu2>0.1</mu2>
 
</gazebo>

<gazebo reference="${prefix}_roll_link">
        <material>Gazebo/Red</material>
        <kp>1000000000000000000000000000.0</kp>
    <kd>1000000000000000000000000000.0</kd>
    <mu1>0.1</mu1>
    <mu2>0.1</mu2>
    </gazebo>
<gazebo reference="${prefix}_pitch_link">
 <kp>1000000000000000000000000000.0</kp>
    <kd>1000000000000000000000000000.0</kd>
    <mu1>0.1</mu1>
    <mu2>0.1</mu2>
    <material>Gazebo/Purple</material>
  </gazebo>
</xacro:macro>
</robot>

