<?xml version="1.0"?>
<robot name="barista_robot">
<material name="blue">
<color rgba = "0 0 1 1"/>
</material>
<material name="white">
<color rgba = "1 1 1 1"/>
</material>
<material name="black">
  <color rgba="0 0 0 1"/>
</material>
<!--chassis-->
<link name="base_footprint">
<origin xyz="0 0 0" rpy="0 0 0"/>
</link>
<link name="chassis">
 <inertial>
    <mass value="4.0"/> 
    <inertia ixx="0.01" iyy="0.004" izz="0.015" ixy="0" ixz="0" iyz="0"/>
</inertial>
<visual>
<geometry>
<cylinder length="0.155" radius="0.178"/>
</geometry>
<origin xyz="0 0 0.1127" rpy=" 0 0 0"/>
<material name="blue"/>
</visual>
<collision>
<geometry>
<cylinder length="0.155" radius="0.178"/>
</geometry>
<origin xyz="0 0 0.1127" rpy=" 0 0 0"/>
</collision>
</link>
<joint name="base_chassis_joint" type="fixed">
<parent link="base_footprint"/>
<child link="chassis"/>
<origin xyz="0 0 0" rpy="0 0 0"/>
</joint>

<!--This is a where we start to add links for wheels-->
<link name="base_left_wheel_link">
  <inertial>
    <mass value="2"/>
    <inertia ixx="0.00013" iyy="0.00013" izz="0.00021" ixy="0" ixz="0" iyz="0"/>
</inertial>
  <visual>
    <geometry>
      <cylinder length="0.0206" radius="0.0352"/>
    </geometry>
    <material name="black"/>
    <origin xyz="0 0 0" rpy="0 0 0"/>  
  </visual>
  <collision>
    <geometry>
      <cylinder length="0.0206" radius="0.0352"/>
    </geometry>
    <origin xyz="0 0 0" rpy="0 0 0"/>  
  </collision>
</link>

<joint name="left_wheel_joint" type="continuous">
  <parent link="chassis"/>
  <child link="base_left_wheel_link"/>
  <origin xyz="0 0.155 0.0352" rpy="-1.57 0 0"/> 
  <axis xyz="0 0 1"/>
  <dynamics friction="0.1"/>
</joint>

<link name="base_right_wheel_link">
 <inertial>
    <mass value="2"/>
    <inertia ixx="0.00013" iyy="0.00013" izz="0.00021" ixy="0" ixz="0" iyz="0"/>
</inertial>

  <visual>
    <geometry>
      <cylinder length="0.0206" radius="0.0352"/>
    </geometry>
    <material name="black"/>
    <origin xyz="0 0 0" rpy="0 0 0"/>  
  </visual>
  <collision>
    <geometry>
      <cylinder length="0.0206" radius="0.0352"/>
    </geometry>
    <origin xyz="0 0 0" rpy="0 0 0"/>  
  </collision>
</link>

<joint name="right_wheel_joint" type="continuous">
  <parent link="chassis"/>
  <child link="base_right_wheel_link"/>
  <origin xyz="0 -0.155 0.0352" rpy="-1.57 0 0"/>  
  <axis xyz="0 0 1"/>
  <dynamics friction="0.1"/>
</joint>

<!--The caster wheel-->
<link name="front_yaw_link">
  <inertial>
    <origin xyz="0 0 0" rpy="0 1.57 1.57"/>
    <mass value="0.5"/> 
    <inertia ixx="0.0002" iyy="0.0002" izz="0.0003" ixy="0" ixz="0" iyz="0"/>
  </inertial>

  <visual>
    <origin xyz="0 0 0" rpy="0 1.57 1.57"/>
    <geometry>
      <cylinder length="0.019" radius="0.025"/>
    </geometry>
    <material name="blue"/>
  </visual>

  <collision>
    <origin xyz="0 0 0" rpy="0 1.57 1.57"/>
    <geometry>
      <cylinder length="0.019" radius="0.025"/>
    </geometry>
  </collision>
</link>

<joint name="front_yaw_joint" type="continuous">
  <parent link="chassis"/>
  <child link="front_yaw_link"/>
  <origin xyz="0.12 0 0.025" rpy="0 0 0"/>
  <axis xyz="0 0 1"/>
  <limit effort="1000.0" velocity="100.0"/>
  <dynamics damping="0.0" friction="0.1"/>
</joint>

<link name="front_pitch_link">
  <inertial>
    <origin xyz="0 0 0" rpy="0 1.57 1.57"/>
    <mass value="0.5"/> 
    <inertia ixx="0.0002" iyy="0.0002" izz="0.0003" ixy="0" ixz="0" iyz="0"/>
  </inertial>

  <visual>
    <origin xyz="0 0 0" rpy="0 1.57 1.57"/>
    <geometry>
      <cylinder length="0.019" radius="0.025"/>
    </geometry>
    <material name="blue"/>
  </visual>

  <collision>
    <origin xyz="0 0 0" rpy="0 1.57 1.57"/>
    <geometry>
      <cylinder length="0.019" radius="0.025"/>
    </geometry>
  </collision>
</link>

<joint name="front_pitch_joint" type="continuous">
  <parent link="front_roll_link"/>
  <child link="front_pitch_link"/>
  <origin xyz="0 0 0" rpy="0 0 0"/>
  <axis xyz="0 1 0"/>
  <limit effort="1000.0" velocity="100.0"/>
  <dynamics damping="0.0" friction="0.1"/>
</joint>

<link name="front_roll_link">
  <inertial>
    <origin xyz="0 0 0" rpy="0 1.57 1.57"/>
    <mass value="0.5"/> 
    <inertia ixx="0.0002" iyy="0.0002" izz="0.0003" ixy="0" ixz="0" iyz="0"/>
  </inertial>

  <visual>
    <origin xyz="0 0 0" rpy="0 1.57 1.57"/>
    <geometry>
      <cylinder length="0.019" radius="0.025"/>
    </geometry>
    <material name="blue"/>
  </visual>

  <collision>
    <origin xyz="0 0 0" rpy="0 1.57 1.57"/>
    <geometry>
      <cylinder length="0.019" radius="0.025"/>
    </geometry>
  </collision>
</link>

<joint name="front_roll_joint" type="continuous">
  <parent link="front_yaw_link"/>
  <child link="front_roll_link"/>
  <origin xyz="0 0 0" rpy="0 0 0"/>
  <axis xyz="1 0 0"/>
  <limit effort="1000.0" velocity="100.0"/>
  <dynamics damping="0.0" friction="0.1"/>
</joint>


<link name="back_yaw_link">
  <inertial>
    <origin xyz="0 0 0" rpy="0 1.57 1.57"/>
    <mass value="0.5"/> 
    <inertia ixx="0.0002" iyy="0.0002" izz="0.0003" ixy="0" ixz="0" iyz="0"/>
  </inertial>

  <visual>
    <origin xyz="0 0 0" rpy="0 1.57 1.57"/>
    <geometry>
      <cylinder length="0.019" radius="0.025"/>
    </geometry>
    <material name="blue"/>
  </visual>

  <collision>
    <origin xyz="0 0 0" rpy="0 1.57 1.57"/>
    <geometry>
      <cylinder length="0.019" radius="0.025"/>
    </geometry>
  </collision>
</link>

<joint name="back_yaw_joint" type="continuous">
  <parent link="chassis"/>
  <child link="back_yaw_link"/>
  <origin xyz="-0.12 0 0.025" rpy="0 0 0"/>
  <axis xyz="0 0 1"/>
  <limit effort="1000.0" velocity="100.0"/>
  <dynamics damping="0.0" friction="0.1"/>
</joint>

<link name="back_pitch_link">
  <inertial>
    <origin xyz="0 0 0" rpy="0 1.57 1.57"/>
    <mass value="0.5"/> 
    <inertia ixx="0.0002" iyy="0.0002" izz="0.0003" ixy="0" ixz="0" iyz="0"/>
  </inertial>

  <visual>
    <origin xyz="0 0 0" rpy="0 1.57 1.57"/>
    <geometry>
      <cylinder length="0.019" radius="0.025"/>
    </geometry>
    <material name="blue"/>
  </visual>

  <collision>
    <origin xyz="0 0 0" rpy="0 1.57 1.57"/>
    <geometry>
      <cylinder length="0.019" radius="0.025"/>
    </geometry>
  </collision>
</link>

<joint name="back_pitch_joint" type="continuous">
  <parent link="back_roll_link"/>
  <child link="back_pitch_link"/>
  <origin xyz="0 0 0" rpy="0 0 0"/>
  <axis xyz="0 1 0"/>
  <limit effort="1000.0" velocity="100.0"/>
  <dynamics damping="0.0" friction="0.1"/>
</joint>

<link name="back_roll_link">
  <inertial>
    <origin xyz="0 0 0" rpy="0 1.57 1.57"/>
    <mass value="0.5"/> 
    <inertia ixx="0.0002" iyy="0.0002" izz="0.0003" ixy="0" ixz="0" iyz="0"/>
  </inertial>

  <visual>
    <origin xyz="0 0 0" rpy="0 1.57 1.57"/>
    <geometry>
      <cylinder length="0.019" radius="0.025"/>
    </geometry>
    <material name="blue"/>
  </visual>

  <collision>
    <origin xyz="0 0 0" rpy="0 1.57 1.57"/>
    <geometry>
      <cylinder length="0.019" radius="0.025"/>
    </geometry>
  </collision>
</link>

<joint name="back_roll_joint" type="continuous">
  <parent link="back_yaw_link"/>
  <child link="back_roll_link"/>
  <origin xyz="0 0 0" rpy="0 0 0"/>
  <axis xyz="0 1 0"/>
  <limit effort="1000.0" velocity="100.0"/>
  <dynamics damping="0.0" friction="0.1"/>
</joint>
<!-- Support rods-->
<link name ="rod_link_1">
<inertial>
<origin xyz="0.05 0.08 0.3" rpy="0 0 0"/>
  <mass value="0.5"/>
  <inertia ixx="0.0001" iyy="0.0001" izz="0.00015" ixy="0" ixz="0" iyz="0"/>
</inertial>
<visual>
<geometry>
<cylinder length="0.22" radius="0.01"/>
</geometry>
<origin xyz="0.05 0.08 0.3" rpy="0 0 0"/>
<material name="white"/>
</visual>
<collision>
<geometry>
<cylinder length="0.22" radius="0.01"/>
</geometry>
<origin xyz="0.1 0.1 0.3" rpy="0 0 0"/>
</collision>
</link>
<joint name="support_chassis_joint1" type="fixed">
<parent link="chassis"/>
<child link="rod_link_1"/>
<origin xyz="0 0 0"/>
</joint>
<!--second rod-->
<link name ="rod_link_2">
<inertial>
<origin xyz="0.1 -0.1 0.3" rpy="0 0 0"/>
  <mass value="0.5"/>
  <inertia ixx="0.0001" iyy="0.0001" izz="0.00015" ixy="0" ixz="0" iyz="0"/>
</inertial>
<visual>
<geometry>
<cylinder length="0.22" radius="0.01"/>
</geometry>
<origin xyz="0.1 -0.1 0.3" rpy="0 0 0"/>
<material name="white"/>
</visual>
<collision>
<geometry>
<cylinder length="0.22" radius="0.01"/>
</geometry>
<origin xyz="0.1 -0.1 0.3" rpy="0 0 0"/>
</collision>
</link>
<joint name="support_chassis_joint2" type="fixed">
<parent link="chassis"/>
<child link="rod_link_2"/>
<origin xyz="0 0 0"/>
</joint>
<!--back rods-->
<link name ="rod_link_3">
<inertial>
<origin xyz="-0.1 0.1 0.3" rpy="0 0 0"/>
  <mass value="0.5"/>
  <inertia ixx="0.0001" iyy="0.0001" izz="0.00015" ixy="0" ixz="0" iyz="0"/>
</inertial>
<visual>
<geometry>
<cylinder length="0.22" radius="0.01"/>
</geometry>
<origin xyz="-0.1 0.1 0.3" rpy="0 0 0"/>
<material name="white"/>
</visual>
<collision>
<geometry>
<cylinder length="0.22" radius="0.01"/>
</geometry>
<origin xyz="-0.1 0.1 0.3" rpy="0 0 0"/>
</collision>
</link>

<joint name="support_chassis_joint3" type="fixed">
<parent link="chassis"/>
<child link="rod_link_3"/>
<origin xyz="0 0 0"/>
</joint>
<!--fourth rod-->
<link name ="rod_link_4">
<inertial>
<origin xyz="-0.1 -0.1 0.3" rpy="0 0 0"/>
  <mass value="0.5"/>
  <inertia ixx="0.0001" iyy="0.0001" izz="0.00015" ixy="0" ixz="0" iyz="0"/>
</inertial>
<visual>
<geometry>
<cylinder length="0.22" radius="0.01"/>
</geometry>
<origin xyz="-0.1 -0.1 0.3" rpy="0 0 0"/>
<material name="white"/>
</visual>
<collision>
<geometry>
<cylinder length="0.22" radius="0.01"/>
</geometry>
<origin xyz="-0.1 -0.1 0.3" rpy="0 0 0"/>
</collision>
</link>
<joint name="support_chassis_joint4" type="fixed">
<parent link="chassis"/>
<child link="rod_link_4"/>
<origin xyz="0 0 0"/>
</joint>
<!--top base -->
<link name="top_base">
<visual>
<geometry>
<cylinder radius="0.16" length="0.09"/>
</geometry>
<origin xyz="0 0 0.436" rpy="0 0 0"/>
<material name="blue"/>
</visual>
<collision>
<geometry>
<cylinder radius="0.16" length="0.09"/>
</geometry>
<origin xyz="0 0 0.44" rpy="0 0 0"/>
</collision>
<inertial>
  <origin xyz="0 0 0.44" rpy="0 0 0"/>
  <mass value="2.0"/>
  <inertia ixx="0.0141" iyy="0.0141" izz="0.0256" ixy="0" ixz="0" iyz="0"/>
</inertial>
</link>
<joint name="top_base_chassis" type="fixed">
<parent link="chassis"/>
<child link="top_base"/>
<origin xyz="0 0 0" rpy="0 0 0"/>
</joint> 
<!--laser scanner-->
<link name = "laser_scan_link">
 <inertial>
    <mass value="1.0"/>
    <inertia ixx="0.00104" ixy="0.0" ixz="0.0"
             iyy="0.00104" iyz="0.0"
             izz="0.0001666"/>
</inertial>

  <visual>
    <geometry>
      <mesh filename="package://barista_robot_description/models/meshes/hokuyo_urg_04lx.dae" scale="1 1 1"/>
     <!-- <box size="0.05 0.05 0.1"/>  -->

    </geometry>
    <origin xyz="0 0 0" rpy="0 0 0"/>
  </visual>
  <collision>
    <geometry>
      <box size="0.1 0.1 0.1"/> 
    </geometry>
    <origin xyz="0 0 0" rpy="0 0 0"/>
  </collision>
</link>

<joint name="laser_joint" type="fixed">
  <parent link="chassis"/>
  <child link="laser_scan_link"/>
  <origin xyz="0.14 0 0.2" rpy="0 0 0"/>
</joint>

<link name="laser_scan_frame">
</link>
<joint name="laser_joint_frame" type="fixed">
<parent link="laser_scan_link"/>
<child link="laser_scan_frame"/>
<origin xyz="0 0 0.05" rpy="0 0 0"/>
</joint>
<!--gazebo-->
<gazebo>
  <material>Gazebo/Blue</material>
  
</gazebo>

<gazebo reference="chassis">
  <material>Gazebo/Blue</material>

</gazebo>

<gazebo reference="base_left_wheel_link">
 <material>Gazebo/Black</material>
    <kp>1000000000000000000000000000.0</kp>
    <kd>1000000000000000000000000000.0</kd>
    <mu1>1.0</mu1>
    <mu2>1.0</mu2>
</gazebo>

<gazebo reference="base_right_wheel_link">
    <material>Gazebo/Black</material>
    <kp>1000000000000000000000000000.0</kp>
    <kd>1000000000000000000000000000.0</kd>
    <mu1>1.0</mu1>
    <mu2>1.0</mu2>
</gazebo>

<gazebo reference="front_yaw_link">
  <material>Gazebo/Blue</material>
  <kp>1000000000000000000000000000.0</kp>
    <kd>1000000000000000000000000000.0</kd>
    <mu1>0.1</mu1>
    <mu2>0.1</mu2>
 
</gazebo>

<gazebo reference="front_roll_link">
        <material>Gazebo/Red</material>
        <kp>1000000000000000000000000000.0</kp>
    <kd>1000000000000000000000000000.0</kd>
    <mu1>0.1</mu1>
    <mu2>0.1</mu2>
    </gazebo>
<gazebo reference="front_pitch_link">
 <kp>1000000000000000000000000000.0</kp>
    <kd>1000000000000000000000000000.0</kd>
    <mu1>0.1</mu1>
    <mu2>0.1</mu2>
    <material>Gazebo/Purple</material>
  </gazebo>
    <gazebo reference="back_pitch_link">
 <kp>1000000000000000000000000000.0</kp>
    <kd>1000000000000000000000000000.0</kd>
    <mu1>0.1</mu1>
    <mu2>0.1</mu2>
    <material>Gazebo/Yellow</material>
  </gazebo>
<gazebo reference="back_yaw_link">
  <material>Gazebo/Blue</material>
  <kp>1000000000000000000000000000.0</kp>
    <kd>1000000000000000000000000000.0</kd>
    <mu1>0.1</mu1>
    <mu2>0.1</mu2>
</gazebo>

<gazebo reference="rod_link_1">
  <material>Gazebo/White</material>
  
</gazebo>

<gazebo reference="rod_link_2">
  <material>Gazebo/White</material>
 
</gazebo>

<gazebo reference="rod_link_3">
  <material>Gazebo/White</material>
 
</gazebo>

<gazebo reference="rod_link_4">
  <material>Gazebo/White</material>
  

</gazebo>

<gazebo reference="top_base">
  <material>Gazebo/Blue</material>
  
</gazebo>


  <gazebo>
    <plugin filename="libgazebo_ros_diff_drive.so" name="differential_drive_controller">

      <!-- wheels -->
      <left_joint>left_wheel_joint</left_joint>
      <right_joint>right_wheel_joint</right_joint>

      <!-- kinematics -->
      <wheel_separation>0.31</wheel_separation>
      <wheel_diameter>0.0704</wheel_diameter>

      <!-- limits -->
      <max_wheel_torque>1.0</max_wheel_torque>
      <max_wheel_acceleration>2.0</max_wheel_acceleration>

      <!-- output -->
      <publish_odom>true</publish_odom>
      <publish_odom_tf>true</publish_odom_tf>

      <odometry_frame>odom</odometry_frame>
      <robot_base_frame>base_footprint</robot_base_frame>

    </plugin>
  </gazebo>
  <gazebo reference="laser_scan_link">
</gazebo>
  
<gazebo reference="laser_scan_frame">
    <sensor name="sensor_ray" type="ray">
        <pose>0 0 0 0 0 0</pose>
        <ray>
          <scan>
            <horizontal>
              <samples>200</samples>
              <resolution>1.0</resolution>
              <min_angle>-1.57</min_angle>
              <max_angle>1.57</max_angle>
            </horizontal>
          </scan>
          <range>
            <min>0.1</min>
            <max>5.0</max>
          </range>
        </ray>
        <always_on>true</always_on>
        <visualize>true</visualize>
        <update_rate>30</update_rate>
        <plugin name="laser" filename="libgazebo_ros_ray_sensor.so">
          <ros>
            <remapping>~/out:=scan</remapping>
          </ros>
          <output_type>sensor_msgs/LaserScan</output_type>
          <frame_name>laser_scan_frame</frame_name>
        </plugin>
    </sensor>
</gazebo>
</robot>
